2024-02-05T00:00:41 {"cpu": 0.19873046875, "cpu_total": 10, "cpu_usage": 0.019873046875, "memory": 2138.0, "memory_total": 3455.0, "memory_usage": 0.6188133140376266, "pipeline_run_id": 7, "pipeline_schedule_id": 2, "pipeline_uuid": "gcs_to_bigquery", "hostname": "5e4287af650d", "level": "INFO", "message": "Pipeline gcs_to_bigquery for run 7 in schedule 2 is alive.", "timestamp": 1707091241.923634, "uuid": "9a3006245923455e8835df5145967371"}
2024-02-05T00:00:42 {"cpu": 0.19873046875, "cpu_total": 10, "cpu_usage": 0.019873046875, "memory": 2155.0, "memory_total": 3455.0, "memory_usage": 0.6237337192474675, "pipeline_run_id": 7, "pipeline_schedule_id": 2, "pipeline_uuid": "gcs_to_bigquery", "hostname": "5e4287af650d", "level": "INFO", "message": "Pipeline gcs_to_bigquery for run 7 in schedule 2 is alive.", "timestamp": 1707091242.007887, "uuid": "9e123566b0ad4f12915d937f40901a5b"}
2024-02-05T00:00:42 {"block_run_id": 19, "block_uuid": "load_taxi_gcs", "pipeline_run_id": 7, "pipeline_schedule_id": 2, "pipeline_uuid": "gcs_to_bigquery", "hostname": "5e4287af650d", "level": "INFO", "message": "Execute PipelineRun 7, BlockRun 19: pipeline gcs_to_bigquery block load_taxi_gcs", "timestamp": 1707091242.07828, "uuid": "268e75bc509d44dd952168975f5b5e42"}
2024-02-05T00:00:47 {"block_run_id": 19, "block_uuid": "load_taxi_gcs", "pipeline_run_id": 7, "pipeline_schedule_id": 2, "pipeline_uuid": "gcs_to_bigquery", "hostname": "5e4287af650d", "level": "INFO", "message": "BlockRun 19 (block_uuid: load_taxi_gcs) completes.", "timestamp": 1707091247.349831, "uuid": "ed2f841faca44fa49ef0faad811f28c1"}
2024-02-05T00:00:51 {"cpu": 0.20166015625, "cpu_total": 10, "cpu_usage": 0.020166015625, "memory": 2097.0, "memory_total": 3455.0, "memory_usage": 0.6069464544138929, "pipeline_run_id": 7, "pipeline_schedule_id": 2, "pipeline_uuid": "gcs_to_bigquery", "hostname": "5e4287af650d", "level": "INFO", "message": "Pipeline gcs_to_bigquery for run 7 in schedule 2 is alive.", "timestamp": 1707091251.320318, "uuid": "e40273372b134998aba04e8d75042fbc"}
2024-02-05T00:00:51 {"block_run_id": 20, "block_uuid": "transformed_staged_data", "pipeline_run_id": 7, "pipeline_schedule_id": 2, "pipeline_uuid": "gcs_to_bigquery", "hostname": "5e4287af650d", "level": "INFO", "message": "Execute PipelineRun 7, BlockRun 20: pipeline gcs_to_bigquery block transformed_staged_data", "timestamp": 1707091251.469457, "uuid": "85162e0bb9f94a89a1201c7fb144b9b5"}
2024-02-05T00:00:54 {"block_run_id": 20, "block_uuid": "transformed_staged_data", "pipeline_run_id": 7, "pipeline_schedule_id": 2, "pipeline_uuid": "gcs_to_bigquery", "hostname": "5e4287af650d", "level": "INFO", "message": "BlockRun 20 (block_uuid: transformed_staged_data) completes.", "timestamp": 1707091254.386387, "uuid": "5a51a4fbd2c4496e8c88462b483cab7f"}
2024-02-05T00:01:01 {"cpu": 0.20458984375, "cpu_total": 10, "cpu_usage": 0.020458984375, "memory": 2057.0, "memory_total": 3455.0, "memory_usage": 0.5953690303907381, "pipeline_run_id": 7, "pipeline_schedule_id": 2, "pipeline_uuid": "gcs_to_bigquery", "hostname": "5e4287af650d", "level": "INFO", "message": "Pipeline gcs_to_bigquery for run 7 in schedule 2 is alive.", "timestamp": 1707091261.518775, "uuid": "c636c7c8d27b44f8b4f34e76d8454764"}
2024-02-05T00:01:01 {"block_run_id": 21, "block_uuid": "write_taxi_to_bigquery", "pipeline_run_id": 7, "pipeline_schedule_id": 2, "pipeline_uuid": "gcs_to_bigquery", "hostname": "5e4287af650d", "level": "INFO", "message": "Execute PipelineRun 7, BlockRun 21: pipeline gcs_to_bigquery block write_taxi_to_bigquery", "timestamp": 1707091261.655511, "uuid": "84bcf66d845a4c08925c399f17f09aeb"}
2024-02-05T00:01:05 {"block_run_id": 21, "block_uuid": "write_taxi_to_bigquery", "pipeline_run_id": 7, "pipeline_schedule_id": 2, "pipeline_uuid": "gcs_to_bigquery", "hostname": "5e4287af650d", "level": "EXCEPTION", "message": "BlockRun 21 (block_uuid: write_taxi_to_bigquery) failed.", "timestamp": 1707091265.017482, "uuid": "4008c8b98ff446cfa7472912ab787792", "error": ["Traceback (most recent call last):\n  File \"/usr/local/lib/python3.10/site-packages/mage_ai/data_preparation/executors/block_executor.py\", line 613, in execute\n    result = __execute_with_retry()\n  File \"/usr/local/lib/python3.10/site-packages/mage_ai/shared/retry.py\", line 54, in retry_func\n    raise e\n  File \"/usr/local/lib/python3.10/site-packages/mage_ai/shared/retry.py\", line 38, in retry_func\n    return func(*args, **kwargs)\n  File \"/usr/local/lib/python3.10/site-packages/mage_ai/data_preparation/executors/block_executor.py\", line 588, in __execute_with_retry\n    return self._execute(\n  File \"/usr/local/lib/python3.10/site-packages/mage_ai/data_preparation/executors/block_executor.py\", line 1077, in _execute\n    result = self.block.execute_sync(\n  File \"/usr/local/lib/python3.10/site-packages/mage_ai/data_preparation/models/block/__init__.py\", line 1312, in execute_sync\n    raise err\n  File \"/usr/local/lib/python3.10/site-packages/mage_ai/data_preparation/models/block/__init__.py\", line 1221, in execute_sync\n    output = self.execute_block(\n  File \"/usr/local/lib/python3.10/site-packages/mage_ai/data_preparation/models/block/__init__.py\", line 1527, in execute_block\n    outputs = self._execute_block(\n  File \"/usr/local/lib/python3.10/site-packages/mage_ai/data_preparation/models/block/sql/__init__.py\", line 721, in _execute_block\n    return execute_sql_code(\n  File \"/usr/local/lib/python3.10/site-packages/mage_ai/data_preparation/models/block/sql/__init__.py\", line 159, in execute_sql_code\n    not is_dynamic and bigquery.create_upstream_block_tables(\n  File \"/usr/local/lib/python3.10/site-packages/mage_ai/data_preparation/models/block/sql/bigquery.py\", line 108, in create_upstream_block_tables\n    loader.export(\n  File \"/usr/local/lib/python3.10/site-packages/mage_ai/io/bigquery.py\", line 321, in export\n    __process(database=database)\n  File \"/usr/local/lib/python3.10/site-packages/mage_ai/io/bigquery.py\", line 293, in __process\n    self.client.create_dataset(dataset=schema, exists_ok=True)\n  File \"/usr/local/lib/python3.10/site-packages/google/cloud/bigquery/client.py\", line 668, in create_dataset\n    api_response = self._call_api(\n  File \"/usr/local/lib/python3.10/site-packages/google/cloud/bigquery/client.py\", line 818, in _call_api\n    return call()\n  File \"/usr/local/lib/python3.10/site-packages/google/api_core/retry.py\", line 372, in retry_wrapped_func\n    return retry_target(\n  File \"/usr/local/lib/python3.10/site-packages/google/api_core/retry.py\", line 207, in retry_target\n    result = target()\n  File \"/usr/local/lib/python3.10/site-packages/google/cloud/_http/__init__.py\", line 482, in api_request\n    response = self._make_request(\n  File \"/usr/local/lib/python3.10/site-packages/google/cloud/_http/__init__.py\", line 341, in _make_request\n    return self._do_request(\n  File \"/usr/local/lib/python3.10/site-packages/google/cloud/_http/__init__.py\", line 379, in _do_request\n    return self.http.request(\n  File \"/usr/local/lib/python3.10/site-packages/google/auth/transport/requests.py\", line 537, in request\n    self.credentials.before_request(auth_request, method, url, request_headers)\n  File \"/usr/local/lib/python3.10/site-packages/google/auth/credentials.py\", line 228, in before_request\n    self._blocking_refresh(request)\n  File \"/usr/local/lib/python3.10/site-packages/google/auth/credentials.py\", line 191, in _blocking_refresh\n    self.refresh(request)\n  File \"/usr/local/lib/python3.10/site-packages/google/oauth2/service_account.py\", line 441, in refresh\n    access_token, expiry, _ = _client.jwt_grant(\n  File \"/usr/local/lib/python3.10/site-packages/google/oauth2/_client.py\", line 308, in jwt_grant\n    response_data = _token_endpoint_request(\n  File \"/usr/local/lib/python3.10/site-packages/google/oauth2/_client.py\", line 279, in _token_endpoint_request\n    _handle_error_response(response_data, retryable_error)\n  File \"/usr/local/lib/python3.10/site-packages/google/oauth2/_client.py\", line 72, in _handle_error_response\n    raise exceptions.RefreshError(\ngoogle.auth.exceptions.RefreshError: ('invalid_grant: Invalid JWT: Token must be a short-lived token (60 minutes) and in a reasonable timeframe. Check your iat and exp values in the JWT claim.', {'error': 'invalid_grant', 'error_description': 'Invalid JWT: Token must be a short-lived token (60 minutes) and in a reasonable timeframe. Check your iat and exp values in the JWT claim.'})\n"], "error_stack": [["  File \"/usr/local/bin/mage\", line 8, in <module>\n    sys.exit(app())\n", "  File \"/usr/local/lib/python3.10/site-packages/typer/main.py\", line 311, in __call__\n    return get_command(self)(*args, **kwargs)\n", "  File \"/usr/local/lib/python3.10/site-packages/click/core.py\", line 1130, in __call__\n    return self.main(*args, **kwargs)\n", "  File \"/usr/local/lib/python3.10/site-packages/typer/core.py\", line 778, in main\n    return _main(\n", "  File \"/usr/local/lib/python3.10/site-packages/typer/core.py\", line 216, in _main\n    rv = self.invoke(ctx)\n", "  File \"/usr/local/lib/python3.10/site-packages/click/core.py\", line 1657, in invoke\n    return _process_result(sub_ctx.command.invoke(sub_ctx))\n", "  File \"/usr/local/lib/python3.10/site-packages/click/core.py\", line 1404, in invoke\n    return ctx.invoke(self.callback, **ctx.params)\n", "  File \"/usr/local/lib/python3.10/site-packages/click/core.py\", line 760, in invoke\n    return __callback(*args, **kwargs)\n", "  File \"/usr/local/lib/python3.10/site-packages/typer/main.py\", line 683, in wrapper\n    return callback(**use_params)  # type: ignore\n", "  File \"/usr/local/lib/python3.10/site-packages/mage_ai/cli/main.py\", line 163, in start\n    start_server(\n", "  File \"/usr/local/lib/python3.10/site-packages/mage_ai/server/server.py\", line 659, in start_server\n    scheduler_manager.start_scheduler()\n", "  File \"/usr/local/lib/python3.10/site-packages/mage_ai/server/scheduler_manager.py\", line 87, in start_scheduler\n    proc.start()\n", "  File \"/usr/local/lib/python3.10/multiprocessing/process.py\", line 121, in start\n    self._popen = self._Popen(self)\n", "  File \"/usr/local/lib/python3.10/multiprocessing/context.py\", line 224, in _Popen\n    return _default_context.get_context().Process._Popen(process_obj)\n", "  File \"/usr/local/lib/python3.10/multiprocessing/context.py\", line 281, in _Popen\n    return Popen(process_obj)\n", "  File \"/usr/local/lib/python3.10/multiprocessing/popen_fork.py\", line 19, in __init__\n    self._launch(process_obj)\n", "  File \"/usr/local/lib/python3.10/multiprocessing/popen_fork.py\", line 71, in _launch\n    code = process_obj._bootstrap(parent_sentinel=child_r)\n", "  File \"/usr/local/lib/python3.10/multiprocessing/process.py\", line 314, in _bootstrap\n    self.run()\n", "  File \"/usr/local/lib/python3.10/multiprocessing/process.py\", line 108, in run\n    self._target(*self._args, **self._kwargs)\n", "  File \"/usr/local/lib/python3.10/site-packages/mage_ai/orchestration/db/process.py\", line 15, in start_session_and_run\n    results = target(*args)\n", "  File \"/usr/local/lib/python3.10/site-packages/mage_ai/server/scheduler_manager.py\", line 50, in run_scheduler\n    LoopTimeTrigger().start()\n", "  File \"/usr/local/lib/python3.10/site-packages/mage_ai/orchestration/triggers/loop_time_trigger.py\", line 14, in start\n    self.run()\n", "  File \"/usr/local/lib/python3.10/site-packages/mage_ai/orchestration/triggers/time_trigger.py\", line 11, in run\n    schedule_all()\n", "  File \"/usr/local/lib/python3.10/site-packages/mage_ai/orchestration/pipeline_scheduler_original.py\", line 1603, in schedule_all\n    PipelineScheduler(r).schedule()\n", "  File \"/usr/local/lib/python3.10/site-packages/mage_ai/orchestration/db/__init__.py\", line 149, in func_with_rollback\n    return func(*args, **kwargs)\n", "  File \"/usr/local/lib/python3.10/site-packages/mage_ai/orchestration/pipeline_scheduler_original.py\", line 319, in schedule\n    self.__schedule_blocks(block_runs)\n", "  File \"/usr/local/lib/python3.10/site-packages/mage_ai/orchestration/pipeline_scheduler_original.py\", line 584, in __schedule_blocks\n    job_manager.add_job(\n", "  File \"/usr/local/lib/python3.10/site-packages/mage_ai/orchestration/job_manager.py\", line 27, in add_job\n    self.queue.enqueue(job_id, target, *args, **kwargs)\n", "  File \"/usr/local/lib/python3.10/site-packages/mage_ai/orchestration/queue/process_queue.py\", line 108, in enqueue\n    self.start_worker_pool()\n", "  File \"/usr/local/lib/python3.10/site-packages/mage_ai/orchestration/queue/process_queue.py\", line 183, in start_worker_pool\n    self.worker_pool_proc.start()\n", "  File \"/usr/local/lib/python3.10/multiprocessing/process.py\", line 121, in start\n    self._popen = self._Popen(self)\n", "  File \"/usr/local/lib/python3.10/multiprocessing/context.py\", line 224, in _Popen\n    return _default_context.get_context().Process._Popen(process_obj)\n", "  File \"/usr/local/lib/python3.10/multiprocessing/context.py\", line 281, in _Popen\n    return Popen(process_obj)\n", "  File \"/usr/local/lib/python3.10/multiprocessing/popen_fork.py\", line 19, in __init__\n    self._launch(process_obj)\n", "  File \"/usr/local/lib/python3.10/multiprocessing/popen_fork.py\", line 71, in _launch\n    code = process_obj._bootstrap(parent_sentinel=child_r)\n", "  File \"/usr/local/lib/python3.10/multiprocessing/process.py\", line 314, in _bootstrap\n    self.run()\n", "  File \"/usr/local/lib/python3.10/multiprocessing/process.py\", line 108, in run\n    self._target(*self._args, **self._kwargs)\n", "  File \"/usr/local/lib/python3.10/site-packages/mage_ai/orchestration/queue/process_queue.py\", line 288, in poll_job_and_execute\n    worker.start()\n", "  File \"/usr/local/lib/python3.10/multiprocessing/process.py\", line 121, in start\n    self._popen = self._Popen(self)\n", "  File \"/usr/local/lib/python3.10/multiprocessing/context.py\", line 224, in _Popen\n    return _default_context.get_context().Process._Popen(process_obj)\n", "  File \"/usr/local/lib/python3.10/multiprocessing/context.py\", line 281, in _Popen\n    return Popen(process_obj)\n", "  File \"/usr/local/lib/python3.10/multiprocessing/popen_fork.py\", line 19, in __init__\n    self._launch(process_obj)\n", "  File \"/usr/local/lib/python3.10/multiprocessing/popen_fork.py\", line 71, in _launch\n    code = process_obj._bootstrap(parent_sentinel=child_r)\n", "  File \"/usr/local/lib/python3.10/multiprocessing/process.py\", line 314, in _bootstrap\n    self.run()\n", "  File \"/usr/local/lib/python3.10/site-packages/newrelic/api/background_task.py\", line 117, in wrapper\n    return wrapped(*args, **kwargs)\n", "  File \"/usr/local/lib/python3.10/site-packages/mage_ai/orchestration/queue/process_queue.py\", line 253, in run\n    start_session_and_run(args[1], *args[2], **args[3])\n", "  File \"/usr/local/lib/python3.10/site-packages/mage_ai/orchestration/db/process.py\", line 15, in start_session_and_run\n    results = target(*args)\n", "  File \"/usr/local/lib/python3.10/site-packages/mage_ai/orchestration/pipeline_scheduler_original.py\", line 1128, in run_block\n    return ExecutorFactory.get_block_executor(\n", "  File \"/usr/local/lib/python3.10/site-packages/mage_ai/data_preparation/executors/block_executor.py\", line 641, in execute\n    on_failure(\n", "  File \"/usr/local/lib/python3.10/site-packages/mage_ai/orchestration/db/__init__.py\", line 149, in func_with_rollback\n    return func(*args, **kwargs)\n", "  File \"/usr/local/lib/python3.10/site-packages/mage_ai/orchestration/pipeline_scheduler_original.py\", line 415, in on_block_failure\n    self.logger.exception(\n", "  File \"/usr/local/lib/python3.10/site-packages/mage_ai/data_preparation/logging/logger.py\", line 30, in exception\n    self.__send_message('exception', message, **kwargs)\n", "  File \"/usr/local/lib/python3.10/site-packages/mage_ai/data_preparation/logging/logger.py\", line 59, in __send_message\n    data['error_stack'] = traceback.format_stack(),\n"]], "error_stacktrace": ["('invalid_grant: Invalid JWT: Token must be a short-lived token (60 minutes) and in a reasonable timeframe. Check your iat and exp values in the JWT claim.', {'error': 'invalid_grant', 'error_description': 'Invalid JWT: Token must be a short-lived token (60 minutes) and in a reasonable timeframe. Check your iat and exp values in the JWT claim.'})"]}
Traceback (most recent call last):
  File "/usr/local/lib/python3.10/site-packages/mage_ai/data_preparation/executors/block_executor.py", line 613, in execute
    result = __execute_with_retry()
  File "/usr/local/lib/python3.10/site-packages/mage_ai/shared/retry.py", line 54, in retry_func
    raise e
  File "/usr/local/lib/python3.10/site-packages/mage_ai/shared/retry.py", line 38, in retry_func
    return func(*args, **kwargs)
  File "/usr/local/lib/python3.10/site-packages/mage_ai/data_preparation/executors/block_executor.py", line 588, in __execute_with_retry
    return self._execute(
  File "/usr/local/lib/python3.10/site-packages/mage_ai/data_preparation/executors/block_executor.py", line 1077, in _execute
    result = self.block.execute_sync(
  File "/usr/local/lib/python3.10/site-packages/mage_ai/data_preparation/models/block/__init__.py", line 1312, in execute_sync
    raise err
  File "/usr/local/lib/python3.10/site-packages/mage_ai/data_preparation/models/block/__init__.py", line 1221, in execute_sync
    output = self.execute_block(
  File "/usr/local/lib/python3.10/site-packages/mage_ai/data_preparation/models/block/__init__.py", line 1527, in execute_block
    outputs = self._execute_block(
  File "/usr/local/lib/python3.10/site-packages/mage_ai/data_preparation/models/block/sql/__init__.py", line 721, in _execute_block
    return execute_sql_code(
  File "/usr/local/lib/python3.10/site-packages/mage_ai/data_preparation/models/block/sql/__init__.py", line 159, in execute_sql_code
    not is_dynamic and bigquery.create_upstream_block_tables(
  File "/usr/local/lib/python3.10/site-packages/mage_ai/data_preparation/models/block/sql/bigquery.py", line 108, in create_upstream_block_tables
    loader.export(
  File "/usr/local/lib/python3.10/site-packages/mage_ai/io/bigquery.py", line 321, in export
    __process(database=database)
  File "/usr/local/lib/python3.10/site-packages/mage_ai/io/bigquery.py", line 293, in __process
    self.client.create_dataset(dataset=schema, exists_ok=True)
  File "/usr/local/lib/python3.10/site-packages/google/cloud/bigquery/client.py", line 668, in create_dataset
    api_response = self._call_api(
  File "/usr/local/lib/python3.10/site-packages/google/cloud/bigquery/client.py", line 818, in _call_api
    return call()
  File "/usr/local/lib/python3.10/site-packages/google/api_core/retry.py", line 372, in retry_wrapped_func
    return retry_target(
  File "/usr/local/lib/python3.10/site-packages/google/api_core/retry.py", line 207, in retry_target
    result = target()
  File "/usr/local/lib/python3.10/site-packages/google/cloud/_http/__init__.py", line 482, in api_request
    response = self._make_request(
  File "/usr/local/lib/python3.10/site-packages/google/cloud/_http/__init__.py", line 341, in _make_request
    return self._do_request(
  File "/usr/local/lib/python3.10/site-packages/google/cloud/_http/__init__.py", line 379, in _do_request
    return self.http.request(
  File "/usr/local/lib/python3.10/site-packages/google/auth/transport/requests.py", line 537, in request
    self.credentials.before_request(auth_request, method, url, request_headers)
  File "/usr/local/lib/python3.10/site-packages/google/auth/credentials.py", line 228, in before_request
    self._blocking_refresh(request)
  File "/usr/local/lib/python3.10/site-packages/google/auth/credentials.py", line 191, in _blocking_refresh
    self.refresh(request)
  File "/usr/local/lib/python3.10/site-packages/google/oauth2/service_account.py", line 441, in refresh
    access_token, expiry, _ = _client.jwt_grant(
  File "/usr/local/lib/python3.10/site-packages/google/oauth2/_client.py", line 308, in jwt_grant
    response_data = _token_endpoint_request(
  File "/usr/local/lib/python3.10/site-packages/google/oauth2/_client.py", line 279, in _token_endpoint_request
    _handle_error_response(response_data, retryable_error)
  File "/usr/local/lib/python3.10/site-packages/google/oauth2/_client.py", line 72, in _handle_error_response
    raise exceptions.RefreshError(
google.auth.exceptions.RefreshError: ('invalid_grant: Invalid JWT: Token must be a short-lived token (60 minutes) and in a reasonable timeframe. Check your iat and exp values in the JWT claim.', {'error': 'invalid_grant', 'error_description': 'Invalid JWT: Token must be a short-lived token (60 minutes) and in a reasonable timeframe. Check your iat and exp values in the JWT claim.'})
2024-02-05T01:22:30 {"cpu": 0.21826171875, "cpu_total": 10, "cpu_usage": 0.021826171875, "memory": 2143.0, "memory_total": 3455.0, "memory_usage": 0.620260492040521, "pipeline_run_id": 7, "pipeline_schedule_id": 2, "pipeline_uuid": "gcs_to_bigquery", "hostname": "5e4287af650d", "level": "INFO", "message": "Pipeline gcs_to_bigquery for run 7 in schedule 2 is alive.", "timestamp": 1707096150.925283, "uuid": "ddad027909d748a3a471fb77bbd87884"}
