2024-02-10T02:11:46 {"cpu": 0.27099609375, "cpu_total": 10, "cpu_usage": 0.027099609375, "memory": 1190.0, "memory_total": 3455.0, "memory_usage": 0.34442836468885674, "pipeline_run_id": 12, "pipeline_schedule_id": 2, "pipeline_uuid": "gcs_to_bigquery", "hostname": "3ffc872bbe37", "level": "INFO", "message": "Pipeline gcs_to_bigquery for run 12 in schedule 2 is alive.", "timestamp": 1707531106.856705, "uuid": "f9ecd1b8cc5744088d3b6ba8df88595f"}
2024-02-10T02:11:46 {"cpu": 0.27099609375, "cpu_total": 10, "cpu_usage": 0.027099609375, "memory": 1236.0, "memory_total": 3455.0, "memory_usage": 0.3577424023154848, "pipeline_run_id": 12, "pipeline_schedule_id": 2, "pipeline_uuid": "gcs_to_bigquery", "hostname": "3ffc872bbe37", "level": "INFO", "message": "Pipeline gcs_to_bigquery for run 12 in schedule 2 is alive.", "timestamp": 1707531106.939551, "uuid": "53ba27ec710048e7abc631348f608e50"}
2024-02-10T02:11:46 {"block_run_id": 34, "block_uuid": "load_taxi_gcs", "pipeline_run_id": 12, "pipeline_schedule_id": 2, "pipeline_uuid": "gcs_to_bigquery", "hostname": "3ffc872bbe37", "level": "INFO", "message": "Execute PipelineRun 12, BlockRun 34: pipeline gcs_to_bigquery block load_taxi_gcs", "timestamp": 1707531106.965201, "uuid": "5bab281de486440cba2202afd272cd09"}
2024-02-10T02:11:48 {"block_run_id": 34, "block_uuid": "load_taxi_gcs", "pipeline_run_id": 12, "pipeline_schedule_id": 2, "pipeline_uuid": "gcs_to_bigquery", "hostname": "3ffc872bbe37", "level": "EXCEPTION", "message": "BlockRun 34 (block_uuid: load_taxi_gcs) failed.", "timestamp": 1707531108.40696, "uuid": "c9683a2f3a234615a74c97f5d3ae3de8", "error": ["Traceback (most recent call last):\n  File \"/usr/local/lib/python3.10/site-packages/mage_ai/data_preparation/executors/block_executor.py\", line 613, in execute\n    result = __execute_with_retry()\n  File \"/usr/local/lib/python3.10/site-packages/mage_ai/shared/retry.py\", line 54, in retry_func\n    raise e\n  File \"/usr/local/lib/python3.10/site-packages/mage_ai/shared/retry.py\", line 38, in retry_func\n    return func(*args, **kwargs)\n  File \"/usr/local/lib/python3.10/site-packages/mage_ai/data_preparation/executors/block_executor.py\", line 588, in __execute_with_retry\n    return self._execute(\n  File \"/usr/local/lib/python3.10/site-packages/mage_ai/data_preparation/executors/block_executor.py\", line 1077, in _execute\n    result = self.block.execute_sync(\n  File \"/usr/local/lib/python3.10/site-packages/mage_ai/data_preparation/models/block/__init__.py\", line 1312, in execute_sync\n    raise err\n  File \"/usr/local/lib/python3.10/site-packages/mage_ai/data_preparation/models/block/__init__.py\", line 1221, in execute_sync\n    output = self.execute_block(\n  File \"/usr/local/lib/python3.10/site-packages/mage_ai/data_preparation/models/block/__init__.py\", line 1527, in execute_block\n    outputs = self._execute_block(\n  File \"/usr/local/lib/python3.10/site-packages/mage_ai/data_preparation/models/block/__init__.py\", line 1683, in _execute_block\n    outputs = self.execute_block_function(\n  File \"/usr/local/lib/python3.10/site-packages/mage_ai/data_preparation/models/block/__init__.py\", line 1722, in execute_block_function\n    output = block_function_updated(*input_vars, **global_vars)\n  File \"<string>\", line 25, in load_from_google_cloud_storage\n  File \"/usr/local/lib/python3.10/site-packages/mage_ai/io/google_cloud_storage.py\", line 95, in load\n    bucket = self.client.get_bucket(bucket_name)\n  File \"/usr/local/lib/python3.10/site-packages/google/cloud/storage/client.py\", line 783, in get_bucket\n    bucket.reload(\n  File \"/usr/local/lib/python3.10/site-packages/google/cloud/storage/bucket.py\", line 1087, in reload\n    super(Bucket, self).reload(\n  File \"/usr/local/lib/python3.10/site-packages/google/cloud/storage/_helpers.py\", line 238, in reload\n    api_response = client._get_resource(\n  File \"/usr/local/lib/python3.10/site-packages/google/cloud/storage/client.py\", line 366, in _get_resource\n    return self._connection.api_request(\n  File \"/usr/local/lib/python3.10/site-packages/google/cloud/storage/_http.py\", line 73, in api_request\n    return call()\n  File \"/usr/local/lib/python3.10/site-packages/google/api_core/retry.py\", line 372, in retry_wrapped_func\n    return retry_target(\n  File \"/usr/local/lib/python3.10/site-packages/google/api_core/retry.py\", line 207, in retry_target\n    result = target()\n  File \"/usr/local/lib/python3.10/site-packages/google/cloud/_http/__init__.py\", line 494, in api_request\n    raise exceptions.from_http_response(response)\ngoogle.api_core.exceptions.Forbidden: 403 GET https://storage.googleapis.com/storage/v1/b/hardy-pattern-413201-de-zoomcamp?projection=noAcl&prettyPrint=false: de-zoomcamp-2024@de-zoomcamp-413815.iam.gserviceaccount.com does not have storage.buckets.get access to the Google Cloud Storage bucket. Permission 'storage.buckets.get' denied on resource (or it may not exist).\n"], "error_stack": [["  File \"/usr/local/bin/mage\", line 8, in <module>\n    sys.exit(app())\n", "  File \"/usr/local/lib/python3.10/site-packages/typer/main.py\", line 311, in __call__\n    return get_command(self)(*args, **kwargs)\n", "  File \"/usr/local/lib/python3.10/site-packages/click/core.py\", line 1130, in __call__\n    return self.main(*args, **kwargs)\n", "  File \"/usr/local/lib/python3.10/site-packages/typer/core.py\", line 778, in main\n    return _main(\n", "  File \"/usr/local/lib/python3.10/site-packages/typer/core.py\", line 216, in _main\n    rv = self.invoke(ctx)\n", "  File \"/usr/local/lib/python3.10/site-packages/click/core.py\", line 1657, in invoke\n    return _process_result(sub_ctx.command.invoke(sub_ctx))\n", "  File \"/usr/local/lib/python3.10/site-packages/click/core.py\", line 1404, in invoke\n    return ctx.invoke(self.callback, **ctx.params)\n", "  File \"/usr/local/lib/python3.10/site-packages/click/core.py\", line 760, in invoke\n    return __callback(*args, **kwargs)\n", "  File \"/usr/local/lib/python3.10/site-packages/typer/main.py\", line 683, in wrapper\n    return callback(**use_params)  # type: ignore\n", "  File \"/usr/local/lib/python3.10/site-packages/mage_ai/cli/main.py\", line 163, in start\n    start_server(\n", "  File \"/usr/local/lib/python3.10/site-packages/mage_ai/server/server.py\", line 659, in start_server\n    scheduler_manager.start_scheduler()\n", "  File \"/usr/local/lib/python3.10/site-packages/mage_ai/server/scheduler_manager.py\", line 87, in start_scheduler\n    proc.start()\n", "  File \"/usr/local/lib/python3.10/multiprocessing/process.py\", line 121, in start\n    self._popen = self._Popen(self)\n", "  File \"/usr/local/lib/python3.10/multiprocessing/context.py\", line 224, in _Popen\n    return _default_context.get_context().Process._Popen(process_obj)\n", "  File \"/usr/local/lib/python3.10/multiprocessing/context.py\", line 281, in _Popen\n    return Popen(process_obj)\n", "  File \"/usr/local/lib/python3.10/multiprocessing/popen_fork.py\", line 19, in __init__\n    self._launch(process_obj)\n", "  File \"/usr/local/lib/python3.10/multiprocessing/popen_fork.py\", line 71, in _launch\n    code = process_obj._bootstrap(parent_sentinel=child_r)\n", "  File \"/usr/local/lib/python3.10/multiprocessing/process.py\", line 314, in _bootstrap\n    self.run()\n", "  File \"/usr/local/lib/python3.10/multiprocessing/process.py\", line 108, in run\n    self._target(*self._args, **self._kwargs)\n", "  File \"/usr/local/lib/python3.10/site-packages/mage_ai/orchestration/db/process.py\", line 15, in start_session_and_run\n    results = target(*args)\n", "  File \"/usr/local/lib/python3.10/site-packages/mage_ai/server/scheduler_manager.py\", line 50, in run_scheduler\n    LoopTimeTrigger().start()\n", "  File \"/usr/local/lib/python3.10/site-packages/mage_ai/orchestration/triggers/loop_time_trigger.py\", line 14, in start\n    self.run()\n", "  File \"/usr/local/lib/python3.10/site-packages/mage_ai/orchestration/triggers/time_trigger.py\", line 11, in run\n    schedule_all()\n", "  File \"/usr/local/lib/python3.10/site-packages/mage_ai/orchestration/pipeline_scheduler_original.py\", line 1575, in schedule_all\n    PipelineScheduler(r).start()\n", "  File \"/usr/local/lib/python3.10/site-packages/mage_ai/orchestration/db/__init__.py\", line 149, in func_with_rollback\n    return func(*args, **kwargs)\n", "  File \"/usr/local/lib/python3.10/site-packages/mage_ai/orchestration/pipeline_scheduler_original.py\", line 182, in start\n    self.schedule()\n", "  File \"/usr/local/lib/python3.10/site-packages/mage_ai/orchestration/db/__init__.py\", line 149, in func_with_rollback\n    return func(*args, **kwargs)\n", "  File \"/usr/local/lib/python3.10/site-packages/mage_ai/orchestration/pipeline_scheduler_original.py\", line 319, in schedule\n    self.__schedule_blocks(block_runs)\n", "  File \"/usr/local/lib/python3.10/site-packages/mage_ai/orchestration/pipeline_scheduler_original.py\", line 584, in __schedule_blocks\n    job_manager.add_job(\n", "  File \"/usr/local/lib/python3.10/site-packages/mage_ai/orchestration/job_manager.py\", line 27, in add_job\n    self.queue.enqueue(job_id, target, *args, **kwargs)\n", "  File \"/usr/local/lib/python3.10/site-packages/mage_ai/orchestration/queue/process_queue.py\", line 108, in enqueue\n    self.start_worker_pool()\n", "  File \"/usr/local/lib/python3.10/site-packages/mage_ai/orchestration/queue/process_queue.py\", line 183, in start_worker_pool\n    self.worker_pool_proc.start()\n", "  File \"/usr/local/lib/python3.10/multiprocessing/process.py\", line 121, in start\n    self._popen = self._Popen(self)\n", "  File \"/usr/local/lib/python3.10/multiprocessing/context.py\", line 224, in _Popen\n    return _default_context.get_context().Process._Popen(process_obj)\n", "  File \"/usr/local/lib/python3.10/multiprocessing/context.py\", line 281, in _Popen\n    return Popen(process_obj)\n", "  File \"/usr/local/lib/python3.10/multiprocessing/popen_fork.py\", line 19, in __init__\n    self._launch(process_obj)\n", "  File \"/usr/local/lib/python3.10/multiprocessing/popen_fork.py\", line 71, in _launch\n    code = process_obj._bootstrap(parent_sentinel=child_r)\n", "  File \"/usr/local/lib/python3.10/multiprocessing/process.py\", line 314, in _bootstrap\n    self.run()\n", "  File \"/usr/local/lib/python3.10/multiprocessing/process.py\", line 108, in run\n    self._target(*self._args, **self._kwargs)\n", "  File \"/usr/local/lib/python3.10/site-packages/mage_ai/orchestration/queue/process_queue.py\", line 288, in poll_job_and_execute\n    worker.start()\n", "  File \"/usr/local/lib/python3.10/multiprocessing/process.py\", line 121, in start\n    self._popen = self._Popen(self)\n", "  File \"/usr/local/lib/python3.10/multiprocessing/context.py\", line 224, in _Popen\n    return _default_context.get_context().Process._Popen(process_obj)\n", "  File \"/usr/local/lib/python3.10/multiprocessing/context.py\", line 281, in _Popen\n    return Popen(process_obj)\n", "  File \"/usr/local/lib/python3.10/multiprocessing/popen_fork.py\", line 19, in __init__\n    self._launch(process_obj)\n", "  File \"/usr/local/lib/python3.10/multiprocessing/popen_fork.py\", line 71, in _launch\n    code = process_obj._bootstrap(parent_sentinel=child_r)\n", "  File \"/usr/local/lib/python3.10/multiprocessing/process.py\", line 314, in _bootstrap\n    self.run()\n", "  File \"/usr/local/lib/python3.10/site-packages/newrelic/api/background_task.py\", line 117, in wrapper\n    return wrapped(*args, **kwargs)\n", "  File \"/usr/local/lib/python3.10/site-packages/mage_ai/orchestration/queue/process_queue.py\", line 253, in run\n    start_session_and_run(args[1], *args[2], **args[3])\n", "  File \"/usr/local/lib/python3.10/site-packages/mage_ai/orchestration/db/process.py\", line 15, in start_session_and_run\n    results = target(*args)\n", "  File \"/usr/local/lib/python3.10/site-packages/mage_ai/orchestration/pipeline_scheduler_original.py\", line 1128, in run_block\n    return ExecutorFactory.get_block_executor(\n", "  File \"/usr/local/lib/python3.10/site-packages/mage_ai/data_preparation/executors/block_executor.py\", line 641, in execute\n    on_failure(\n", "  File \"/usr/local/lib/python3.10/site-packages/mage_ai/orchestration/db/__init__.py\", line 149, in func_with_rollback\n    return func(*args, **kwargs)\n", "  File \"/usr/local/lib/python3.10/site-packages/mage_ai/orchestration/pipeline_scheduler_original.py\", line 415, in on_block_failure\n    self.logger.exception(\n", "  File \"/usr/local/lib/python3.10/site-packages/mage_ai/data_preparation/logging/logger.py\", line 30, in exception\n    self.__send_message('exception', message, **kwargs)\n", "  File \"/usr/local/lib/python3.10/site-packages/mage_ai/data_preparation/logging/logger.py\", line 59, in __send_message\n    data['error_stack'] = traceback.format_stack(),\n"]], "error_stacktrace": ["403 GET https://storage.googleapis.com/storage/v1/b/hardy-pattern-413201-de-zoomcamp?projection=noAcl&prettyPrint=false: de-zoomcamp-2024@de-zoomcamp-413815.iam.gserviceaccount.com does not have storage.buckets.get access to the Google Cloud Storage bucket. Permission 'storage.buckets.get' denied on resource (or it may not exist)."]}
Traceback (most recent call last):
  File "/usr/local/lib/python3.10/site-packages/mage_ai/data_preparation/executors/block_executor.py", line 613, in execute
    result = __execute_with_retry()
  File "/usr/local/lib/python3.10/site-packages/mage_ai/shared/retry.py", line 54, in retry_func
    raise e
  File "/usr/local/lib/python3.10/site-packages/mage_ai/shared/retry.py", line 38, in retry_func
    return func(*args, **kwargs)
  File "/usr/local/lib/python3.10/site-packages/mage_ai/data_preparation/executors/block_executor.py", line 588, in __execute_with_retry
    return self._execute(
  File "/usr/local/lib/python3.10/site-packages/mage_ai/data_preparation/executors/block_executor.py", line 1077, in _execute
    result = self.block.execute_sync(
  File "/usr/local/lib/python3.10/site-packages/mage_ai/data_preparation/models/block/__init__.py", line 1312, in execute_sync
    raise err
  File "/usr/local/lib/python3.10/site-packages/mage_ai/data_preparation/models/block/__init__.py", line 1221, in execute_sync
    output = self.execute_block(
  File "/usr/local/lib/python3.10/site-packages/mage_ai/data_preparation/models/block/__init__.py", line 1527, in execute_block
    outputs = self._execute_block(
  File "/usr/local/lib/python3.10/site-packages/mage_ai/data_preparation/models/block/__init__.py", line 1683, in _execute_block
    outputs = self.execute_block_function(
  File "/usr/local/lib/python3.10/site-packages/mage_ai/data_preparation/models/block/__init__.py", line 1722, in execute_block_function
    output = block_function_updated(*input_vars, **global_vars)
  File "<string>", line 25, in load_from_google_cloud_storage
  File "/usr/local/lib/python3.10/site-packages/mage_ai/io/google_cloud_storage.py", line 95, in load
    bucket = self.client.get_bucket(bucket_name)
  File "/usr/local/lib/python3.10/site-packages/google/cloud/storage/client.py", line 783, in get_bucket
    bucket.reload(
  File "/usr/local/lib/python3.10/site-packages/google/cloud/storage/bucket.py", line 1087, in reload
    super(Bucket, self).reload(
  File "/usr/local/lib/python3.10/site-packages/google/cloud/storage/_helpers.py", line 238, in reload
    api_response = client._get_resource(
  File "/usr/local/lib/python3.10/site-packages/google/cloud/storage/client.py", line 366, in _get_resource
    return self._connection.api_request(
  File "/usr/local/lib/python3.10/site-packages/google/cloud/storage/_http.py", line 73, in api_request
    return call()
  File "/usr/local/lib/python3.10/site-packages/google/api_core/retry.py", line 372, in retry_wrapped_func
    return retry_target(
  File "/usr/local/lib/python3.10/site-packages/google/api_core/retry.py", line 207, in retry_target
    result = target()
  File "/usr/local/lib/python3.10/site-packages/google/cloud/_http/__init__.py", line 494, in api_request
    raise exceptions.from_http_response(response)
google.api_core.exceptions.Forbidden: 403 GET https://storage.googleapis.com/storage/v1/b/hardy-pattern-413201-de-zoomcamp?projection=noAcl&prettyPrint=false: de-zoomcamp-2024@de-zoomcamp-413815.iam.gserviceaccount.com does not have storage.buckets.get access to the Google Cloud Storage bucket. Permission 'storage.buckets.get' denied on resource (or it may not exist).
2024-02-10T02:12:09 {"cpu": 0.26806640625, "cpu_total": 10, "cpu_usage": 0.026806640625, "memory": 1457.0, "memory_total": 3455.0, "memory_usage": 0.42170767004341536, "pipeline_run_id": 12, "pipeline_schedule_id": 2, "pipeline_uuid": "gcs_to_bigquery", "hostname": "3ffc872bbe37", "level": "INFO", "message": "Pipeline gcs_to_bigquery for run 12 in schedule 2 is alive.", "timestamp": 1707531129.852634, "uuid": "68849bf68cd24e86a3e5616b8c0a1169"}
