2024-02-07T00:31:50 {"cpu": 0.21435546875, "cpu_total": 10, "cpu_usage": 0.021435546875, "memory": 1919.0, "memory_total": 3455.0, "memory_usage": 0.5554269175108538, "pipeline_run_id": 9, "pipeline_schedule_id": 2, "pipeline_uuid": "gcs_to_bigquery", "hostname": "bf709a44e279", "level": "INFO", "message": "Pipeline gcs_to_bigquery for run 9 in schedule 2 is alive.", "timestamp": 1707265910.228873, "uuid": "ad7ddb48b46f4908ae298ac1371defea"}
2024-02-07T00:31:50 {"cpu": 0.21435546875, "cpu_total": 10, "cpu_usage": 0.021435546875, "memory": 1938.0, "memory_total": 3455.0, "memory_usage": 0.5609261939218524, "pipeline_run_id": 9, "pipeline_schedule_id": 2, "pipeline_uuid": "gcs_to_bigquery", "hostname": "bf709a44e279", "level": "INFO", "message": "Pipeline gcs_to_bigquery for run 9 in schedule 2 is alive.", "timestamp": 1707265910.298332, "uuid": "10ac31ccf62440869f81381baa40e88e"}
2024-02-07T00:31:50 {"block_run_id": 25, "block_uuid": "load_taxi_gcs", "pipeline_run_id": 9, "pipeline_schedule_id": 2, "pipeline_uuid": "gcs_to_bigquery", "hostname": "bf709a44e279", "level": "INFO", "message": "Execute PipelineRun 9, BlockRun 25: pipeline gcs_to_bigquery block load_taxi_gcs", "timestamp": 1707265910.341563, "uuid": "a15673c586aa4b5aa1492dbaa344dc5a"}
2024-02-07T00:31:55 {"block_run_id": 25, "block_uuid": "load_taxi_gcs", "pipeline_run_id": 9, "pipeline_schedule_id": 2, "pipeline_uuid": "gcs_to_bigquery", "hostname": "bf709a44e279", "level": "INFO", "message": "BlockRun 25 (block_uuid: load_taxi_gcs) completes.", "timestamp": 1707265915.118507, "uuid": "89ae281616c04c9d8c9e330dec4c449c"}
2024-02-07T00:32:00 {"cpu": 0.21142578125, "cpu_total": 10, "cpu_usage": 0.021142578125, "memory": 1853.0, "memory_total": 3455.0, "memory_usage": 0.5363241678726484, "pipeline_run_id": 9, "pipeline_schedule_id": 2, "pipeline_uuid": "gcs_to_bigquery", "hostname": "bf709a44e279", "level": "INFO", "message": "Pipeline gcs_to_bigquery for run 9 in schedule 2 is alive.", "timestamp": 1707265920.45259, "uuid": "4078a2d366b14faf9327c11dc1a59730"}
2024-02-07T00:32:10 {"cpu": 0.20849609375, "cpu_total": 10, "cpu_usage": 0.020849609375, "memory": 1835.0, "memory_total": 3455.0, "memory_usage": 0.5311143270622286, "pipeline_run_id": 9, "pipeline_schedule_id": 2, "pipeline_uuid": "gcs_to_bigquery", "hostname": "bf709a44e279", "level": "INFO", "message": "Pipeline gcs_to_bigquery for run 9 in schedule 2 is alive.", "timestamp": 1707265930.570059, "uuid": "8d26cc3069214ada959c8fa76a8ab237"}
2024-02-07T00:32:10 {"block_run_id": 26, "block_uuid": "transformed_staged_data", "pipeline_run_id": 9, "pipeline_schedule_id": 2, "pipeline_uuid": "gcs_to_bigquery", "hostname": "bf709a44e279", "level": "INFO", "message": "Execute PipelineRun 9, BlockRun 26: pipeline gcs_to_bigquery block transformed_staged_data", "timestamp": 1707265930.673507, "uuid": "08966e5fa7414e189cd16de7af581b87"}
2024-02-07T00:32:12 {"block_run_id": 26, "block_uuid": "transformed_staged_data", "pipeline_run_id": 9, "pipeline_schedule_id": 2, "pipeline_uuid": "gcs_to_bigquery", "hostname": "bf709a44e279", "level": "INFO", "message": "BlockRun 26 (block_uuid: transformed_staged_data) completes.", "timestamp": 1707265932.967885, "uuid": "bfe71875125742b297361e7c0382d147"}
2024-02-07T00:48:41 {"cpu": 0.21728515625, "cpu_total": 10, "cpu_usage": 0.021728515625, "memory": 1823.0, "memory_total": 3455.0, "memory_usage": 0.5276410998552822, "pipeline_run_id": 9, "pipeline_schedule_id": 2, "pipeline_uuid": "gcs_to_bigquery", "hostname": "bf709a44e279", "level": "INFO", "message": "Pipeline gcs_to_bigquery for run 9 in schedule 2 is alive.", "timestamp": 1707266921.533241, "uuid": "f5ba94e8493846eaaec1f744b4729a44"}
2024-02-07T00:48:41 {"block_run_id": 27, "block_uuid": "write_taxi_to_bigquery", "pipeline_run_id": 9, "pipeline_schedule_id": 2, "pipeline_uuid": "gcs_to_bigquery", "hostname": "bf709a44e279", "level": "INFO", "message": "Execute PipelineRun 9, BlockRun 27: pipeline gcs_to_bigquery block write_taxi_to_bigquery", "timestamp": 1707266921.658418, "uuid": "d4f0411ef9e945c8ace7a258515440e9"}
2024-02-07T00:48:51 {"cpu": 0.22607421875, "cpu_total": 10, "cpu_usage": 0.022607421875, "memory": 2934.0, "memory_total": 3455.0, "memory_usage": 0.8492040520984081, "pipeline_run_id": 9, "pipeline_schedule_id": 2, "pipeline_uuid": "gcs_to_bigquery", "hostname": "bf709a44e279", "level": "INFO", "message": "Pipeline gcs_to_bigquery for run 9 in schedule 2 is alive.", "timestamp": 1707266931.736389, "uuid": "f78201108c3d4cf8949e77599f86c29d"}
2024-02-07T00:49:01 {"cpu": 0.23486328125, "cpu_total": 10, "cpu_usage": 0.023486328125, "memory": 2947.0, "memory_total": 3455.0, "memory_usage": 0.8529667149059335, "pipeline_run_id": 9, "pipeline_schedule_id": 2, "pipeline_uuid": "gcs_to_bigquery", "hostname": "bf709a44e279", "level": "INFO", "message": "Pipeline gcs_to_bigquery for run 9 in schedule 2 is alive.", "timestamp": 1707266941.815248, "uuid": "2ebe2ee95db543cb8f85211f9e8857e3"}
2024-02-07T01:03:13 {"cpu": 0.23779296875, "cpu_total": 10, "cpu_usage": 0.023779296875, "memory": 2963.0, "memory_total": 3455.0, "memory_usage": 0.8575976845151954, "pipeline_run_id": 9, "pipeline_schedule_id": 2, "pipeline_uuid": "gcs_to_bigquery", "hostname": "bf709a44e279", "level": "INFO", "message": "Pipeline gcs_to_bigquery for run 9 in schedule 2 is alive.", "timestamp": 1707267793.249191, "uuid": "640c6841150149dc8e9ffe69cb02b13d"}
2024-02-07T01:03:23 {"cpu": 0.24072265625, "cpu_total": 10, "cpu_usage": 0.024072265625, "memory": 2968.0, "memory_total": 3455.0, "memory_usage": 0.8590448625180898, "pipeline_run_id": 9, "pipeline_schedule_id": 2, "pipeline_uuid": "gcs_to_bigquery", "hostname": "bf709a44e279", "level": "INFO", "message": "Pipeline gcs_to_bigquery for run 9 in schedule 2 is alive.", "timestamp": 1707267803.334981, "uuid": "31a7dca1462e4c339a6616047625183a"}
2024-02-07T01:03:33 {"cpu": 0.23779296875, "cpu_total": 10, "cpu_usage": 0.023779296875, "memory": 2968.0, "memory_total": 3455.0, "memory_usage": 0.8590448625180898, "pipeline_run_id": 9, "pipeline_schedule_id": 2, "pipeline_uuid": "gcs_to_bigquery", "hostname": "bf709a44e279", "level": "INFO", "message": "Pipeline gcs_to_bigquery for run 9 in schedule 2 is alive.", "timestamp": 1707267813.45675, "uuid": "ca631f6f3d824880911e80a30e9514c7"}
2024-02-07T01:03:43 {"cpu": 0.23486328125, "cpu_total": 10, "cpu_usage": 0.023486328125, "memory": 2969.0, "memory_total": 3455.0, "memory_usage": 0.8593342981186686, "pipeline_run_id": 9, "pipeline_schedule_id": 2, "pipeline_uuid": "gcs_to_bigquery", "hostname": "bf709a44e279", "level": "INFO", "message": "Pipeline gcs_to_bigquery for run 9 in schedule 2 is alive.", "timestamp": 1707267823.576484, "uuid": "9e4289d3fafe4faf912827cf656743f0"}
2024-02-07T01:03:53 {"cpu": 0.23193359375, "cpu_total": 10, "cpu_usage": 0.023193359375, "memory": 2978.0, "memory_total": 3455.0, "memory_usage": 0.8619392185238784, "pipeline_run_id": 9, "pipeline_schedule_id": 2, "pipeline_uuid": "gcs_to_bigquery", "hostname": "bf709a44e279", "level": "INFO", "message": "Pipeline gcs_to_bigquery for run 9 in schedule 2 is alive.", "timestamp": 1707267833.709453, "uuid": "c8d23568a959411f8c48b214c9ba6033"}
2024-02-07T01:04:03 {"cpu": 0.22900390625, "cpu_total": 10, "cpu_usage": 0.022900390625, "memory": 2976.0, "memory_total": 3455.0, "memory_usage": 0.8613603473227207, "pipeline_run_id": 9, "pipeline_schedule_id": 2, "pipeline_uuid": "gcs_to_bigquery", "hostname": "bf709a44e279", "level": "INFO", "message": "Pipeline gcs_to_bigquery for run 9 in schedule 2 is alive.", "timestamp": 1707267843.794172, "uuid": "e1374d848bc0462a94210825fe1e3736"}
2024-02-07T01:04:14 {"cpu": 0.22607421875, "cpu_total": 10, "cpu_usage": 0.022607421875, "memory": 2992.0, "memory_total": 3455.0, "memory_usage": 0.8659913169319826, "pipeline_run_id": 9, "pipeline_schedule_id": 2, "pipeline_uuid": "gcs_to_bigquery", "hostname": "bf709a44e279", "level": "INFO", "message": "Pipeline gcs_to_bigquery for run 9 in schedule 2 is alive.", "timestamp": 1707267854.214794, "uuid": "e22f2e71b36c44afac50eff380a291f5"}
2024-02-07T01:04:24 {"cpu": 0.23974609375, "cpu_total": 10, "cpu_usage": 0.023974609375, "memory": 2995.0, "memory_total": 3455.0, "memory_usage": 0.8668596237337193, "pipeline_run_id": 9, "pipeline_schedule_id": 2, "pipeline_uuid": "gcs_to_bigquery", "hostname": "bf709a44e279", "level": "INFO", "message": "Pipeline gcs_to_bigquery for run 9 in schedule 2 is alive.", "timestamp": 1707267864.306598, "uuid": "3ba3d564b7444c7fb85d2b944f8b20b7"}
2024-02-07T01:04:34 {"cpu": 0.23681640625, "cpu_total": 10, "cpu_usage": 0.023681640625, "memory": 3002.0, "memory_total": 3455.0, "memory_usage": 0.8688856729377713, "pipeline_run_id": 9, "pipeline_schedule_id": 2, "pipeline_uuid": "gcs_to_bigquery", "hostname": "bf709a44e279", "level": "INFO", "message": "Pipeline gcs_to_bigquery for run 9 in schedule 2 is alive.", "timestamp": 1707267874.424325, "uuid": "70acbf2ea28e4642b953d573ae6cd07e"}
2024-02-07T01:04:44 {"cpu": 0.23388671875, "cpu_total": 10, "cpu_usage": 0.023388671875, "memory": 2999.0, "memory_total": 3455.0, "memory_usage": 0.8680173661360348, "pipeline_run_id": 9, "pipeline_schedule_id": 2, "pipeline_uuid": "gcs_to_bigquery", "hostname": "bf709a44e279", "level": "INFO", "message": "Pipeline gcs_to_bigquery for run 9 in schedule 2 is alive.", "timestamp": 1707267884.532098, "uuid": "66c3897ca87a41e595f685ac4c9b7bb5"}
2024-02-07T01:04:54 {"cpu": 0.23095703125, "cpu_total": 10, "cpu_usage": 0.023095703125, "memory": 3004.0, "memory_total": 3455.0, "memory_usage": 0.869464544138929, "pipeline_run_id": 9, "pipeline_schedule_id": 2, "pipeline_uuid": "gcs_to_bigquery", "hostname": "bf709a44e279", "level": "INFO", "message": "Pipeline gcs_to_bigquery for run 9 in schedule 2 is alive.", "timestamp": 1707267894.63228, "uuid": "d8adb6ec39e94179b8182bfe5520e676"}
2024-02-07T01:05:04 {"cpu": 0.22802734375, "cpu_total": 10, "cpu_usage": 0.022802734375, "memory": 3003.0, "memory_total": 3455.0, "memory_usage": 0.8691751085383502, "pipeline_run_id": 9, "pipeline_schedule_id": 2, "pipeline_uuid": "gcs_to_bigquery", "hostname": "bf709a44e279", "level": "INFO", "message": "Pipeline gcs_to_bigquery for run 9 in schedule 2 is alive.", "timestamp": 1707267904.739686, "uuid": "cf938122480f4fd783a4519d49e9a89b"}
2024-02-07T01:05:14 {"cpu": 0.22509765625, "cpu_total": 10, "cpu_usage": 0.022509765625, "memory": 3010.0, "memory_total": 3455.0, "memory_usage": 0.8712011577424024, "pipeline_run_id": 9, "pipeline_schedule_id": 2, "pipeline_uuid": "gcs_to_bigquery", "hostname": "bf709a44e279", "level": "INFO", "message": "Pipeline gcs_to_bigquery for run 9 in schedule 2 is alive.", "timestamp": 1707267914.833283, "uuid": "a2c9b6964f34413c8083475278125a17"}
2024-02-07T01:05:17 {"block_run_id": 27, "block_uuid": "write_taxi_to_bigquery", "pipeline_run_id": 9, "pipeline_schedule_id": 2, "pipeline_uuid": "gcs_to_bigquery", "hostname": "bf709a44e279", "level": "EXCEPTION", "message": "BlockRun 27 (block_uuid: write_taxi_to_bigquery) failed.", "timestamp": 1707267917.265633, "uuid": "414b29504cf34dfc85fccea58d96ff0d", "error": ["Traceback (most recent call last):\n  File \"/usr/local/lib/python3.10/site-packages/urllib3/connectionpool.py\", line 715, in urlopen\n    httplib_response = self._make_request(\n  File \"/usr/local/lib/python3.10/site-packages/urllib3/connectionpool.py\", line 467, in _make_request\n    six.raise_from(e, None)\n  File \"<string>\", line 3, in raise_from\n  File \"/usr/local/lib/python3.10/site-packages/urllib3/connectionpool.py\", line 462, in _make_request\n    httplib_response = conn.getresponse()\n  File \"/usr/local/lib/python3.10/http/client.py\", line 1375, in getresponse\n    response.begin()\n  File \"/usr/local/lib/python3.10/http/client.py\", line 318, in begin\n    version, status, reason = self._read_status()\n  File \"/usr/local/lib/python3.10/http/client.py\", line 287, in _read_status\n    raise RemoteDisconnected(\"Remote end closed connection without\"\nhttp.client.RemoteDisconnected: Remote end closed connection without response\n\nDuring handling of the above exception, another exception occurred:\n\nTraceback (most recent call last):\n  File \"/usr/local/lib/python3.10/site-packages/requests/adapters.py\", line 486, in send\n    resp = conn.urlopen(\n  File \"/usr/local/lib/python3.10/site-packages/urllib3/connectionpool.py\", line 799, in urlopen\n    retries = retries.increment(\n  File \"/usr/local/lib/python3.10/site-packages/urllib3/util/retry.py\", line 550, in increment\n    raise six.reraise(type(error), error, _stacktrace)\n  File \"/usr/local/lib/python3.10/site-packages/urllib3/packages/six.py\", line 769, in reraise\n    raise value.with_traceback(tb)\n  File \"/usr/local/lib/python3.10/site-packages/urllib3/connectionpool.py\", line 715, in urlopen\n    httplib_response = self._make_request(\n  File \"/usr/local/lib/python3.10/site-packages/urllib3/connectionpool.py\", line 467, in _make_request\n    six.raise_from(e, None)\n  File \"<string>\", line 3, in raise_from\n  File \"/usr/local/lib/python3.10/site-packages/urllib3/connectionpool.py\", line 462, in _make_request\n    httplib_response = conn.getresponse()\n  File \"/usr/local/lib/python3.10/http/client.py\", line 1375, in getresponse\n    response.begin()\n  File \"/usr/local/lib/python3.10/http/client.py\", line 318, in begin\n    version, status, reason = self._read_status()\n  File \"/usr/local/lib/python3.10/http/client.py\", line 287, in _read_status\n    raise RemoteDisconnected(\"Remote end closed connection without\"\nurllib3.exceptions.ProtocolError: ('Connection aborted.', RemoteDisconnected('Remote end closed connection without response'))\n\nDuring handling of the above exception, another exception occurred:\n\nTraceback (most recent call last):\n  File \"/usr/local/lib/python3.10/site-packages/google/api_core/retry.py\", line 207, in retry_target\n    result = target()\n  File \"/usr/local/lib/python3.10/site-packages/google/cloud/_http/__init__.py\", line 482, in api_request\n    response = self._make_request(\n  File \"/usr/local/lib/python3.10/site-packages/google/cloud/_http/__init__.py\", line 341, in _make_request\n    return self._do_request(\n  File \"/usr/local/lib/python3.10/site-packages/google/cloud/_http/__init__.py\", line 379, in _do_request\n    return self.http.request(\n  File \"/usr/local/lib/python3.10/site-packages/google/auth/transport/requests.py\", line 541, in request\n    response = super(AuthorizedSession, self).request(\n  File \"/usr/local/lib/python3.10/site-packages/requests/sessions.py\", line 589, in request\n    resp = self.send(prep, **send_kwargs)\n  File \"/usr/local/lib/python3.10/site-packages/requests/sessions.py\", line 703, in send\n    r = adapter.send(request, **kwargs)\n  File \"/usr/local/lib/python3.10/site-packages/requests/adapters.py\", line 501, in send\n    raise ConnectionError(err, request=request)\nrequests.exceptions.ConnectionError: ('Connection aborted.', RemoteDisconnected('Remote end closed connection without response'))\n\nThe above exception was the direct cause of the following exception:\n\nTraceback (most recent call last):\n  File \"/usr/local/lib/python3.10/site-packages/mage_ai/data_preparation/executors/block_executor.py\", line 613, in execute\n    result = __execute_with_retry()\n  File \"/usr/local/lib/python3.10/site-packages/mage_ai/shared/retry.py\", line 54, in retry_func\n    raise e\n  File \"/usr/local/lib/python3.10/site-packages/mage_ai/shared/retry.py\", line 38, in retry_func\n    return func(*args, **kwargs)\n  File \"/usr/local/lib/python3.10/site-packages/mage_ai/data_preparation/executors/block_executor.py\", line 588, in __execute_with_retry\n    return self._execute(\n  File \"/usr/local/lib/python3.10/site-packages/mage_ai/data_preparation/executors/block_executor.py\", line 1077, in _execute\n    result = self.block.execute_sync(\n  File \"/usr/local/lib/python3.10/site-packages/mage_ai/data_preparation/models/block/__init__.py\", line 1312, in execute_sync\n    raise err\n  File \"/usr/local/lib/python3.10/site-packages/mage_ai/data_preparation/models/block/__init__.py\", line 1221, in execute_sync\n    output = self.execute_block(\n  File \"/usr/local/lib/python3.10/site-packages/mage_ai/data_preparation/models/block/__init__.py\", line 1527, in execute_block\n    outputs = self._execute_block(\n  File \"/usr/local/lib/python3.10/site-packages/mage_ai/data_preparation/models/block/sql/__init__.py\", line 721, in _execute_block\n    return execute_sql_code(\n  File \"/usr/local/lib/python3.10/site-packages/mage_ai/data_preparation/models/block/sql/__init__.py\", line 159, in execute_sql_code\n    not is_dynamic and bigquery.create_upstream_block_tables(\n  File \"/usr/local/lib/python3.10/site-packages/mage_ai/data_preparation/models/block/sql/bigquery.py\", line 108, in create_upstream_block_tables\n    loader.export(\n  File \"/usr/local/lib/python3.10/site-packages/mage_ai/io/bigquery.py\", line 321, in export\n    __process(database=database)\n  File \"/usr/local/lib/python3.10/site-packages/mage_ai/io/bigquery.py\", line 295, in __process\n    column_types = self.get_column_types(schema, table_name)\n  File \"/usr/local/lib/python3.10/site-packages/mage_ai/io/bigquery.py\", line 83, in get_column_types\n    results = self.client.query(f\"\"\"\n  File \"/usr/local/lib/python3.10/site-packages/google/cloud/bigquery/client.py\", line 3387, in query\n    return _job_helpers.query_jobs_insert(\n  File \"/usr/local/lib/python3.10/site-packages/google/cloud/bigquery/_job_helpers.py\", line 158, in query_jobs_insert\n    future = do_query()\n  File \"/usr/local/lib/python3.10/site-packages/google/cloud/bigquery/_job_helpers.py\", line 135, in do_query\n    query_job._begin(retry=retry, timeout=timeout)\n  File \"/usr/local/lib/python3.10/site-packages/google/cloud/bigquery/job/query.py\", line 1379, in _begin\n    super(QueryJob, self)._begin(client=client, retry=retry, timeout=timeout)\n  File \"/usr/local/lib/python3.10/site-packages/google/cloud/bigquery/job/base.py\", line 723, in _begin\n    api_response = client._call_api(\n  File \"/usr/local/lib/python3.10/site-packages/google/cloud/bigquery/client.py\", line 818, in _call_api\n    return call()\n  File \"/usr/local/lib/python3.10/site-packages/google/api_core/retry.py\", line 372, in retry_wrapped_func\n    return retry_target(\n  File \"/usr/local/lib/python3.10/site-packages/google/api_core/retry.py\", line 226, in retry_target\n    raise exceptions.RetryError(\ngoogle.api_core.exceptions.RetryError: Deadline of 600.0s exceeded while calling target function, last exception: ('Connection aborted.', RemoteDisconnected('Remote end closed connection without response'))\n"], "error_stack": [["  File \"/usr/local/bin/mage\", line 8, in <module>\n    sys.exit(app())\n", "  File \"/usr/local/lib/python3.10/site-packages/typer/main.py\", line 311, in __call__\n    return get_command(self)(*args, **kwargs)\n", "  File \"/usr/local/lib/python3.10/site-packages/click/core.py\", line 1130, in __call__\n    return self.main(*args, **kwargs)\n", "  File \"/usr/local/lib/python3.10/site-packages/typer/core.py\", line 778, in main\n    return _main(\n", "  File \"/usr/local/lib/python3.10/site-packages/typer/core.py\", line 216, in _main\n    rv = self.invoke(ctx)\n", "  File \"/usr/local/lib/python3.10/site-packages/click/core.py\", line 1657, in invoke\n    return _process_result(sub_ctx.command.invoke(sub_ctx))\n", "  File \"/usr/local/lib/python3.10/site-packages/click/core.py\", line 1404, in invoke\n    return ctx.invoke(self.callback, **ctx.params)\n", "  File \"/usr/local/lib/python3.10/site-packages/click/core.py\", line 760, in invoke\n    return __callback(*args, **kwargs)\n", "  File \"/usr/local/lib/python3.10/site-packages/typer/main.py\", line 683, in wrapper\n    return callback(**use_params)  # type: ignore\n", "  File \"/usr/local/lib/python3.10/site-packages/mage_ai/cli/main.py\", line 163, in start\n    start_server(\n", "  File \"/usr/local/lib/python3.10/site-packages/mage_ai/server/server.py\", line 659, in start_server\n    scheduler_manager.start_scheduler()\n", "  File \"/usr/local/lib/python3.10/site-packages/mage_ai/server/scheduler_manager.py\", line 87, in start_scheduler\n    proc.start()\n", "  File \"/usr/local/lib/python3.10/multiprocessing/process.py\", line 121, in start\n    self._popen = self._Popen(self)\n", "  File \"/usr/local/lib/python3.10/multiprocessing/context.py\", line 224, in _Popen\n    return _default_context.get_context().Process._Popen(process_obj)\n", "  File \"/usr/local/lib/python3.10/multiprocessing/context.py\", line 281, in _Popen\n    return Popen(process_obj)\n", "  File \"/usr/local/lib/python3.10/multiprocessing/popen_fork.py\", line 19, in __init__\n    self._launch(process_obj)\n", "  File \"/usr/local/lib/python3.10/multiprocessing/popen_fork.py\", line 71, in _launch\n    code = process_obj._bootstrap(parent_sentinel=child_r)\n", "  File \"/usr/local/lib/python3.10/multiprocessing/process.py\", line 314, in _bootstrap\n    self.run()\n", "  File \"/usr/local/lib/python3.10/multiprocessing/process.py\", line 108, in run\n    self._target(*self._args, **self._kwargs)\n", "  File \"/usr/local/lib/python3.10/site-packages/mage_ai/orchestration/db/process.py\", line 15, in start_session_and_run\n    results = target(*args)\n", "  File \"/usr/local/lib/python3.10/site-packages/mage_ai/server/scheduler_manager.py\", line 50, in run_scheduler\n    LoopTimeTrigger().start()\n", "  File \"/usr/local/lib/python3.10/site-packages/mage_ai/orchestration/triggers/loop_time_trigger.py\", line 14, in start\n    self.run()\n", "  File \"/usr/local/lib/python3.10/site-packages/mage_ai/orchestration/triggers/time_trigger.py\", line 11, in run\n    schedule_all()\n", "  File \"/usr/local/lib/python3.10/site-packages/mage_ai/orchestration/pipeline_scheduler_original.py\", line 1603, in schedule_all\n    PipelineScheduler(r).schedule()\n", "  File \"/usr/local/lib/python3.10/site-packages/mage_ai/orchestration/db/__init__.py\", line 149, in func_with_rollback\n    return func(*args, **kwargs)\n", "  File \"/usr/local/lib/python3.10/site-packages/mage_ai/orchestration/pipeline_scheduler_original.py\", line 319, in schedule\n    self.__schedule_blocks(block_runs)\n", "  File \"/usr/local/lib/python3.10/site-packages/mage_ai/orchestration/pipeline_scheduler_original.py\", line 584, in __schedule_blocks\n    job_manager.add_job(\n", "  File \"/usr/local/lib/python3.10/site-packages/mage_ai/orchestration/job_manager.py\", line 27, in add_job\n    self.queue.enqueue(job_id, target, *args, **kwargs)\n", "  File \"/usr/local/lib/python3.10/site-packages/mage_ai/orchestration/queue/process_queue.py\", line 108, in enqueue\n    self.start_worker_pool()\n", "  File \"/usr/local/lib/python3.10/site-packages/mage_ai/orchestration/queue/process_queue.py\", line 183, in start_worker_pool\n    self.worker_pool_proc.start()\n", "  File \"/usr/local/lib/python3.10/multiprocessing/process.py\", line 121, in start\n    self._popen = self._Popen(self)\n", "  File \"/usr/local/lib/python3.10/multiprocessing/context.py\", line 224, in _Popen\n    return _default_context.get_context().Process._Popen(process_obj)\n", "  File \"/usr/local/lib/python3.10/multiprocessing/context.py\", line 281, in _Popen\n    return Popen(process_obj)\n", "  File \"/usr/local/lib/python3.10/multiprocessing/popen_fork.py\", line 19, in __init__\n    self._launch(process_obj)\n", "  File \"/usr/local/lib/python3.10/multiprocessing/popen_fork.py\", line 71, in _launch\n    code = process_obj._bootstrap(parent_sentinel=child_r)\n", "  File \"/usr/local/lib/python3.10/multiprocessing/process.py\", line 314, in _bootstrap\n    self.run()\n", "  File \"/usr/local/lib/python3.10/multiprocessing/process.py\", line 108, in run\n    self._target(*self._args, **self._kwargs)\n", "  File \"/usr/local/lib/python3.10/site-packages/mage_ai/orchestration/queue/process_queue.py\", line 288, in poll_job_and_execute\n    worker.start()\n", "  File \"/usr/local/lib/python3.10/multiprocessing/process.py\", line 121, in start\n    self._popen = self._Popen(self)\n", "  File \"/usr/local/lib/python3.10/multiprocessing/context.py\", line 224, in _Popen\n    return _default_context.get_context().Process._Popen(process_obj)\n", "  File \"/usr/local/lib/python3.10/multiprocessing/context.py\", line 281, in _Popen\n    return Popen(process_obj)\n", "  File \"/usr/local/lib/python3.10/multiprocessing/popen_fork.py\", line 19, in __init__\n    self._launch(process_obj)\n", "  File \"/usr/local/lib/python3.10/multiprocessing/popen_fork.py\", line 71, in _launch\n    code = process_obj._bootstrap(parent_sentinel=child_r)\n", "  File \"/usr/local/lib/python3.10/multiprocessing/process.py\", line 314, in _bootstrap\n    self.run()\n", "  File \"/usr/local/lib/python3.10/site-packages/newrelic/api/background_task.py\", line 117, in wrapper\n    return wrapped(*args, **kwargs)\n", "  File \"/usr/local/lib/python3.10/site-packages/mage_ai/orchestration/queue/process_queue.py\", line 253, in run\n    start_session_and_run(args[1], *args[2], **args[3])\n", "  File \"/usr/local/lib/python3.10/site-packages/mage_ai/orchestration/db/process.py\", line 15, in start_session_and_run\n    results = target(*args)\n", "  File \"/usr/local/lib/python3.10/site-packages/mage_ai/orchestration/pipeline_scheduler_original.py\", line 1128, in run_block\n    return ExecutorFactory.get_block_executor(\n", "  File \"/usr/local/lib/python3.10/site-packages/mage_ai/data_preparation/executors/block_executor.py\", line 641, in execute\n    on_failure(\n", "  File \"/usr/local/lib/python3.10/site-packages/mage_ai/orchestration/db/__init__.py\", line 149, in func_with_rollback\n    return func(*args, **kwargs)\n", "  File \"/usr/local/lib/python3.10/site-packages/mage_ai/orchestration/pipeline_scheduler_original.py\", line 415, in on_block_failure\n    self.logger.exception(\n", "  File \"/usr/local/lib/python3.10/site-packages/mage_ai/data_preparation/logging/logger.py\", line 30, in exception\n    self.__send_message('exception', message, **kwargs)\n", "  File \"/usr/local/lib/python3.10/site-packages/mage_ai/data_preparation/logging/logger.py\", line 59, in __send_message\n    data['error_stack'] = traceback.format_stack(),\n"]], "error_stacktrace": ["Deadline of 600.0s exceeded while calling target function, last exception: ('Connection aborted.', RemoteDisconnected('Remote end closed connection without response'))"]}
Traceback (most recent call last):
  File "/usr/local/lib/python3.10/site-packages/urllib3/connectionpool.py", line 715, in urlopen
    httplib_response = self._make_request(
  File "/usr/local/lib/python3.10/site-packages/urllib3/connectionpool.py", line 467, in _make_request
    six.raise_from(e, None)
  File "<string>", line 3, in raise_from
  File "/usr/local/lib/python3.10/site-packages/urllib3/connectionpool.py", line 462, in _make_request
    httplib_response = conn.getresponse()
  File "/usr/local/lib/python3.10/http/client.py", line 1375, in getresponse
    response.begin()
  File "/usr/local/lib/python3.10/http/client.py", line 318, in begin
    version, status, reason = self._read_status()
  File "/usr/local/lib/python3.10/http/client.py", line 287, in _read_status
    raise RemoteDisconnected("Remote end closed connection without"
http.client.RemoteDisconnected: Remote end closed connection without response

During handling of the above exception, another exception occurred:

Traceback (most recent call last):
  File "/usr/local/lib/python3.10/site-packages/requests/adapters.py", line 486, in send
    resp = conn.urlopen(
  File "/usr/local/lib/python3.10/site-packages/urllib3/connectionpool.py", line 799, in urlopen
    retries = retries.increment(
  File "/usr/local/lib/python3.10/site-packages/urllib3/util/retry.py", line 550, in increment
    raise six.reraise(type(error), error, _stacktrace)
  File "/usr/local/lib/python3.10/site-packages/urllib3/packages/six.py", line 769, in reraise
    raise value.with_traceback(tb)
  File "/usr/local/lib/python3.10/site-packages/urllib3/connectionpool.py", line 715, in urlopen
    httplib_response = self._make_request(
  File "/usr/local/lib/python3.10/site-packages/urllib3/connectionpool.py", line 467, in _make_request
    six.raise_from(e, None)
  File "<string>", line 3, in raise_from
  File "/usr/local/lib/python3.10/site-packages/urllib3/connectionpool.py", line 462, in _make_request
    httplib_response = conn.getresponse()
  File "/usr/local/lib/python3.10/http/client.py", line 1375, in getresponse
    response.begin()
  File "/usr/local/lib/python3.10/http/client.py", line 318, in begin
    version, status, reason = self._read_status()
  File "/usr/local/lib/python3.10/http/client.py", line 287, in _read_status
    raise RemoteDisconnected("Remote end closed connection without"
urllib3.exceptions.ProtocolError: ('Connection aborted.', RemoteDisconnected('Remote end closed connection without response'))

During handling of the above exception, another exception occurred:

Traceback (most recent call last):
  File "/usr/local/lib/python3.10/site-packages/google/api_core/retry.py", line 207, in retry_target
    result = target()
  File "/usr/local/lib/python3.10/site-packages/google/cloud/_http/__init__.py", line 482, in api_request
    response = self._make_request(
  File "/usr/local/lib/python3.10/site-packages/google/cloud/_http/__init__.py", line 341, in _make_request
    return self._do_request(
  File "/usr/local/lib/python3.10/site-packages/google/cloud/_http/__init__.py", line 379, in _do_request
    return self.http.request(
  File "/usr/local/lib/python3.10/site-packages/google/auth/transport/requests.py", line 541, in request
    response = super(AuthorizedSession, self).request(
  File "/usr/local/lib/python3.10/site-packages/requests/sessions.py", line 589, in request
    resp = self.send(prep, **send_kwargs)
  File "/usr/local/lib/python3.10/site-packages/requests/sessions.py", line 703, in send
    r = adapter.send(request, **kwargs)
  File "/usr/local/lib/python3.10/site-packages/requests/adapters.py", line 501, in send
    raise ConnectionError(err, request=request)
requests.exceptions.ConnectionError: ('Connection aborted.', RemoteDisconnected('Remote end closed connection without response'))

The above exception was the direct cause of the following exception:

Traceback (most recent call last):
  File "/usr/local/lib/python3.10/site-packages/mage_ai/data_preparation/executors/block_executor.py", line 613, in execute
    result = __execute_with_retry()
  File "/usr/local/lib/python3.10/site-packages/mage_ai/shared/retry.py", line 54, in retry_func
    raise e
  File "/usr/local/lib/python3.10/site-packages/mage_ai/shared/retry.py", line 38, in retry_func
    return func(*args, **kwargs)
  File "/usr/local/lib/python3.10/site-packages/mage_ai/data_preparation/executors/block_executor.py", line 588, in __execute_with_retry
    return self._execute(
  File "/usr/local/lib/python3.10/site-packages/mage_ai/data_preparation/executors/block_executor.py", line 1077, in _execute
    result = self.block.execute_sync(
  File "/usr/local/lib/python3.10/site-packages/mage_ai/data_preparation/models/block/__init__.py", line 1312, in execute_sync
    raise err
  File "/usr/local/lib/python3.10/site-packages/mage_ai/data_preparation/models/block/__init__.py", line 1221, in execute_sync
    output = self.execute_block(
  File "/usr/local/lib/python3.10/site-packages/mage_ai/data_preparation/models/block/__init__.py", line 1527, in execute_block
    outputs = self._execute_block(
  File "/usr/local/lib/python3.10/site-packages/mage_ai/data_preparation/models/block/sql/__init__.py", line 721, in _execute_block
    return execute_sql_code(
  File "/usr/local/lib/python3.10/site-packages/mage_ai/data_preparation/models/block/sql/__init__.py", line 159, in execute_sql_code
    not is_dynamic and bigquery.create_upstream_block_tables(
  File "/usr/local/lib/python3.10/site-packages/mage_ai/data_preparation/models/block/sql/bigquery.py", line 108, in create_upstream_block_tables
    loader.export(
  File "/usr/local/lib/python3.10/site-packages/mage_ai/io/bigquery.py", line 321, in export
    __process(database=database)
  File "/usr/local/lib/python3.10/site-packages/mage_ai/io/bigquery.py", line 295, in __process
    column_types = self.get_column_types(schema, table_name)
  File "/usr/local/lib/python3.10/site-packages/mage_ai/io/bigquery.py", line 83, in get_column_types
    results = self.client.query(f"""
  File "/usr/local/lib/python3.10/site-packages/google/cloud/bigquery/client.py", line 3387, in query
    return _job_helpers.query_jobs_insert(
  File "/usr/local/lib/python3.10/site-packages/google/cloud/bigquery/_job_helpers.py", line 158, in query_jobs_insert
    future = do_query()
  File "/usr/local/lib/python3.10/site-packages/google/cloud/bigquery/_job_helpers.py", line 135, in do_query
    query_job._begin(retry=retry, timeout=timeout)
  File "/usr/local/lib/python3.10/site-packages/google/cloud/bigquery/job/query.py", line 1379, in _begin
    super(QueryJob, self)._begin(client=client, retry=retry, timeout=timeout)
  File "/usr/local/lib/python3.10/site-packages/google/cloud/bigquery/job/base.py", line 723, in _begin
    api_response = client._call_api(
  File "/usr/local/lib/python3.10/site-packages/google/cloud/bigquery/client.py", line 818, in _call_api
    return call()
  File "/usr/local/lib/python3.10/site-packages/google/api_core/retry.py", line 372, in retry_wrapped_func
    return retry_target(
  File "/usr/local/lib/python3.10/site-packages/google/api_core/retry.py", line 226, in retry_target
    raise exceptions.RetryError(
google.api_core.exceptions.RetryError: Deadline of 600.0s exceeded while calling target function, last exception: ('Connection aborted.', RemoteDisconnected('Remote end closed connection without response'))
2024-02-07T01:05:24 {"cpu": 0.23193359375, "cpu_total": 10, "cpu_usage": 0.023193359375, "memory": 1827.0, "memory_total": 3455.0, "memory_usage": 0.5287988422575977, "pipeline_run_id": 9, "pipeline_schedule_id": 2, "pipeline_uuid": "gcs_to_bigquery", "hostname": "bf709a44e279", "level": "INFO", "message": "Pipeline gcs_to_bigquery for run 9 in schedule 2 is alive.", "timestamp": 1707267924.966046, "uuid": "cf70736babf945fd8a09fa13c136282a"}
